Internal Server Error: /
Traceback (most recent call last):
  File "/Users/bochkovoy/PycharmProjects/KiraProject/.venv/lib/python3.8/site-packages/django/core/handlers/exception.py", line 55, in inner
    response = get_response(request)
  File "/Users/bochkovoy/PycharmProjects/KiraProject/.venv/lib/python3.8/site-packages/django/core/handlers/base.py", line 197, in _get_response
    response = wrapped_callback(request, *callback_args, **callback_kwargs)
  File "/Users/bochkovoy/PycharmProjects/KiraProject/landscapedesign/main/views.py", line 15, in home
    featured_services = Service.objects.filter(is_featured=True)[:3]
  File "/Users/bochkovoy/PycharmProjects/KiraProject/.venv/lib/python3.8/site-packages/django/db/models/manager.py", line 87, in manager_method
    return getattr(self.get_queryset(), name)(*args, **kwargs)
  File "/Users/bochkovoy/PycharmProjects/KiraProject/.venv/lib/python3.8/site-packages/django/db/models/query.py", line 1436, in filter
    return self._filter_or_exclude(False, args, kwargs)
  File "/Users/bochkovoy/PycharmProjects/KiraProject/.venv/lib/python3.8/site-packages/django/db/models/query.py", line 1454, in _filter_or_exclude
    clone._filter_or_exclude_inplace(negate, args, kwargs)
  File "/Users/bochkovoy/PycharmProjects/KiraProject/.venv/lib/python3.8/site-packages/django/db/models/query.py", line 1461, in _filter_or_exclude_inplace
    self._query.add_q(Q(*args, **kwargs))
  File "/Users/bochkovoy/PycharmProjects/KiraProject/.venv/lib/python3.8/site-packages/django/db/models/sql/query.py", line 1546, in add_q
    clause, _ = self._add_q(q_object, self.used_aliases)
  File "/Users/bochkovoy/PycharmProjects/KiraProject/.venv/lib/python3.8/site-packages/django/db/models/sql/query.py", line 1577, in _add_q
    child_clause, needed_inner = self.build_filter(
  File "/Users/bochkovoy/PycharmProjects/KiraProject/.venv/lib/python3.8/site-packages/django/db/models/sql/query.py", line 1427, in build_filter
    lookups, parts, reffed_expression = self.solve_lookup_type(arg, summarize)
  File "/Users/bochkovoy/PycharmProjects/KiraProject/.venv/lib/python3.8/site-packages/django/db/models/sql/query.py", line 1237, in solve_lookup_type
    _, field, _, lookup_parts = self.names_to_path(lookup_splitted, self.get_meta())
  File "/Users/bochkovoy/PycharmProjects/KiraProject/.venv/lib/python3.8/site-packages/django/db/models/sql/query.py", line 1725, in names_to_path
    raise FieldError(
django.core.exceptions.FieldError: Cannot resolve keyword 'is_featured' into field. Choices are: description, highlight_on_main, id, image, name
Internal Server Error: /
Traceback (most recent call last):
  File "/Users/bochkovoy/PycharmProjects/KiraProject/.venv/lib/python3.8/site-packages/django/core/handlers/exception.py", line 55, in inner
    response = get_response(request)
  File "/Users/bochkovoy/PycharmProjects/KiraProject/.venv/lib/python3.8/site-packages/django/core/handlers/base.py", line 197, in _get_response
    response = wrapped_callback(request, *callback_args, **callback_kwargs)
  File "/Users/bochkovoy/PycharmProjects/KiraProject/landscapedesign/main/views.py", line 15, in home
    featured_services = Service.objects.filter(is_featured=True)[:3]
  File "/Users/bochkovoy/PycharmProjects/KiraProject/.venv/lib/python3.8/site-packages/django/db/models/manager.py", line 87, in manager_method
    return getattr(self.get_queryset(), name)(*args, **kwargs)
  File "/Users/bochkovoy/PycharmProjects/KiraProject/.venv/lib/python3.8/site-packages/django/db/models/query.py", line 1436, in filter
    return self._filter_or_exclude(False, args, kwargs)
  File "/Users/bochkovoy/PycharmProjects/KiraProject/.venv/lib/python3.8/site-packages/django/db/models/query.py", line 1454, in _filter_or_exclude
    clone._filter_or_exclude_inplace(negate, args, kwargs)
  File "/Users/bochkovoy/PycharmProjects/KiraProject/.venv/lib/python3.8/site-packages/django/db/models/query.py", line 1461, in _filter_or_exclude_inplace
    self._query.add_q(Q(*args, **kwargs))
  File "/Users/bochkovoy/PycharmProjects/KiraProject/.venv/lib/python3.8/site-packages/django/db/models/sql/query.py", line 1546, in add_q
    clause, _ = self._add_q(q_object, self.used_aliases)
  File "/Users/bochkovoy/PycharmProjects/KiraProject/.venv/lib/python3.8/site-packages/django/db/models/sql/query.py", line 1577, in _add_q
    child_clause, needed_inner = self.build_filter(
  File "/Users/bochkovoy/PycharmProjects/KiraProject/.venv/lib/python3.8/site-packages/django/db/models/sql/query.py", line 1427, in build_filter
    lookups, parts, reffed_expression = self.solve_lookup_type(arg, summarize)
  File "/Users/bochkovoy/PycharmProjects/KiraProject/.venv/lib/python3.8/site-packages/django/db/models/sql/query.py", line 1237, in solve_lookup_type
    _, field, _, lookup_parts = self.names_to_path(lookup_splitted, self.get_meta())
  File "/Users/bochkovoy/PycharmProjects/KiraProject/.venv/lib/python3.8/site-packages/django/db/models/sql/query.py", line 1725, in names_to_path
    raise FieldError(
django.core.exceptions.FieldError: Cannot resolve keyword 'is_featured' into field. Choices are: description, highlight_on_main, id, image, name
"GET / HTTP/1.1" 500 104867
"GET / HTTP/1.1" 500 104867
Internal Server Error: /
Traceback (most recent call last):
  File "/Users/bochkovoy/PycharmProjects/KiraProject/.venv/lib/python3.8/site-packages/django/utils/module_loading.py", line 30, in import_string
    return cached_import(module_path, class_name)
  File "/Users/bochkovoy/PycharmProjects/KiraProject/.venv/lib/python3.8/site-packages/django/utils/module_loading.py", line 16, in cached_import
    return getattr(module, class_name)
AttributeError: module 'main.context_processors' has no attribute 'contact_info'

The above exception was the direct cause of the following exception:

Traceback (most recent call last):
  File "/Users/bochkovoy/PycharmProjects/KiraProject/.venv/lib/python3.8/site-packages/django/core/handlers/exception.py", line 55, in inner
    response = get_response(request)
  File "/Users/bochkovoy/PycharmProjects/KiraProject/.venv/lib/python3.8/site-packages/django/core/handlers/base.py", line 197, in _get_response
    response = wrapped_callback(request, *callback_args, **callback_kwargs)
  File "/Users/bochkovoy/PycharmProjects/KiraProject/landscapedesign/main/views.py", line 24, in home
    return render(request, 'index.html', context)
  File "/Users/bochkovoy/PycharmProjects/KiraProject/.venv/lib/python3.8/site-packages/django/shortcuts.py", line 24, in render
    content = loader.render_to_string(template_name, context, request, using=using)
  File "/Users/bochkovoy/PycharmProjects/KiraProject/.venv/lib/python3.8/site-packages/django/template/loader.py", line 62, in render_to_string
    return template.render(context, request)
  File "/Users/bochkovoy/PycharmProjects/KiraProject/.venv/lib/python3.8/site-packages/django/template/backends/django.py", line 61, in render
    return self.template.render(context)
  File "/Users/bochkovoy/PycharmProjects/KiraProject/.venv/lib/python3.8/site-packages/django/template/base.py", line 173, in render
    with context.bind_template(self):
  File "/usr/local/opt/python@3.8/Frameworks/Python.framework/Versions/3.8/lib/python3.8/contextlib.py", line 113, in __enter__
    return next(self.gen)
  File "/Users/bochkovoy/PycharmProjects/KiraProject/.venv/lib/python3.8/site-packages/django/template/context.py", line 251, in bind_template
    processors = template.engine.template_context_processors + self._processors
  File "/Users/bochkovoy/PycharmProjects/KiraProject/.venv/lib/python3.8/site-packages/django/utils/functional.py", line 57, in __get__
    res = instance.__dict__[self.name] = self.func(instance)
  File "/Users/bochkovoy/PycharmProjects/KiraProject/.venv/lib/python3.8/site-packages/django/template/engine.py", line 116, in template_context_processors
    return tuple(import_string(path) for path in context_processors)
  File "/Users/bochkovoy/PycharmProjects/KiraProject/.venv/lib/python3.8/site-packages/django/template/engine.py", line 116, in <genexpr>
    return tuple(import_string(path) for path in context_processors)
  File "/Users/bochkovoy/PycharmProjects/KiraProject/.venv/lib/python3.8/site-packages/django/utils/module_loading.py", line 32, in import_string
    raise ImportError(
ImportError: Module "main.context_processors" does not define a "contact_info" attribute/class
Internal Server Error: /
Traceback (most recent call last):
  File "/Users/bochkovoy/PycharmProjects/KiraProject/.venv/lib/python3.8/site-packages/django/utils/module_loading.py", line 30, in import_string
    return cached_import(module_path, class_name)
  File "/Users/bochkovoy/PycharmProjects/KiraProject/.venv/lib/python3.8/site-packages/django/utils/module_loading.py", line 16, in cached_import
    return getattr(module, class_name)
AttributeError: module 'main.context_processors' has no attribute 'contact_info'

The above exception was the direct cause of the following exception:

Traceback (most recent call last):
  File "/Users/bochkovoy/PycharmProjects/KiraProject/.venv/lib/python3.8/site-packages/django/core/handlers/exception.py", line 55, in inner
    response = get_response(request)
  File "/Users/bochkovoy/PycharmProjects/KiraProject/.venv/lib/python3.8/site-packages/django/core/handlers/base.py", line 197, in _get_response
    response = wrapped_callback(request, *callback_args, **callback_kwargs)
  File "/Users/bochkovoy/PycharmProjects/KiraProject/landscapedesign/main/views.py", line 24, in home
    return render(request, 'index.html', context)
  File "/Users/bochkovoy/PycharmProjects/KiraProject/.venv/lib/python3.8/site-packages/django/shortcuts.py", line 24, in render
    content = loader.render_to_string(template_name, context, request, using=using)
  File "/Users/bochkovoy/PycharmProjects/KiraProject/.venv/lib/python3.8/site-packages/django/template/loader.py", line 62, in render_to_string
    return template.render(context, request)
  File "/Users/bochkovoy/PycharmProjects/KiraProject/.venv/lib/python3.8/site-packages/django/template/backends/django.py", line 61, in render
    return self.template.render(context)
  File "/Users/bochkovoy/PycharmProjects/KiraProject/.venv/lib/python3.8/site-packages/django/template/base.py", line 173, in render
    with context.bind_template(self):
  File "/usr/local/opt/python@3.8/Frameworks/Python.framework/Versions/3.8/lib/python3.8/contextlib.py", line 113, in __enter__
    return next(self.gen)
  File "/Users/bochkovoy/PycharmProjects/KiraProject/.venv/lib/python3.8/site-packages/django/template/context.py", line 251, in bind_template
    processors = template.engine.template_context_processors + self._processors
  File "/Users/bochkovoy/PycharmProjects/KiraProject/.venv/lib/python3.8/site-packages/django/utils/functional.py", line 57, in __get__
    res = instance.__dict__[self.name] = self.func(instance)
  File "/Users/bochkovoy/PycharmProjects/KiraProject/.venv/lib/python3.8/site-packages/django/template/engine.py", line 116, in template_context_processors
    return tuple(import_string(path) for path in context_processors)
  File "/Users/bochkovoy/PycharmProjects/KiraProject/.venv/lib/python3.8/site-packages/django/template/engine.py", line 116, in <genexpr>
    return tuple(import_string(path) for path in context_processors)
  File "/Users/bochkovoy/PycharmProjects/KiraProject/.venv/lib/python3.8/site-packages/django/utils/module_loading.py", line 32, in import_string
    raise ImportError(
ImportError: Module "main.context_processors" does not define a "contact_info" attribute/class
"GET / HTTP/1.1" 500 115582
"GET / HTTP/1.1" 500 115582
Internal Server Error: /
Traceback (most recent call last):
  File "/Users/bochkovoy/PycharmProjects/KiraProject/.venv/lib/python3.8/site-packages/django/utils/module_loading.py", line 30, in import_string
    return cached_import(module_path, class_name)
  File "/Users/bochkovoy/PycharmProjects/KiraProject/.venv/lib/python3.8/site-packages/django/utils/module_loading.py", line 16, in cached_import
    return getattr(module, class_name)
AttributeError: module 'main.context_processors' has no attribute 'contact_info'

The above exception was the direct cause of the following exception:

Traceback (most recent call last):
  File "/Users/bochkovoy/PycharmProjects/KiraProject/.venv/lib/python3.8/site-packages/django/core/handlers/exception.py", line 55, in inner
    response = get_response(request)
  File "/Users/bochkovoy/PycharmProjects/KiraProject/.venv/lib/python3.8/site-packages/django/core/handlers/base.py", line 197, in _get_response
    response = wrapped_callback(request, *callback_args, **callback_kwargs)
  File "/Users/bochkovoy/PycharmProjects/KiraProject/landscapedesign/main/views.py", line 24, in home
    return render(request, 'index.html', context)
  File "/Users/bochkovoy/PycharmProjects/KiraProject/.venv/lib/python3.8/site-packages/django/shortcuts.py", line 24, in render
    content = loader.render_to_string(template_name, context, request, using=using)
  File "/Users/bochkovoy/PycharmProjects/KiraProject/.venv/lib/python3.8/site-packages/django/template/loader.py", line 62, in render_to_string
    return template.render(context, request)
  File "/Users/bochkovoy/PycharmProjects/KiraProject/.venv/lib/python3.8/site-packages/django/template/backends/django.py", line 61, in render
    return self.template.render(context)
  File "/Users/bochkovoy/PycharmProjects/KiraProject/.venv/lib/python3.8/site-packages/django/template/base.py", line 173, in render
    with context.bind_template(self):
  File "/usr/local/opt/python@3.8/Frameworks/Python.framework/Versions/3.8/lib/python3.8/contextlib.py", line 113, in __enter__
    return next(self.gen)
  File "/Users/bochkovoy/PycharmProjects/KiraProject/.venv/lib/python3.8/site-packages/django/template/context.py", line 251, in bind_template
    processors = template.engine.template_context_processors + self._processors
  File "/Users/bochkovoy/PycharmProjects/KiraProject/.venv/lib/python3.8/site-packages/django/utils/functional.py", line 57, in __get__
    res = instance.__dict__[self.name] = self.func(instance)
  File "/Users/bochkovoy/PycharmProjects/KiraProject/.venv/lib/python3.8/site-packages/django/template/engine.py", line 116, in template_context_processors
    return tuple(import_string(path) for path in context_processors)
  File "/Users/bochkovoy/PycharmProjects/KiraProject/.venv/lib/python3.8/site-packages/django/template/engine.py", line 116, in <genexpr>
    return tuple(import_string(path) for path in context_processors)
  File "/Users/bochkovoy/PycharmProjects/KiraProject/.venv/lib/python3.8/site-packages/django/utils/module_loading.py", line 32, in import_string
    raise ImportError(
ImportError: Module "main.context_processors" does not define a "contact_info" attribute/class
Internal Server Error: /
Traceback (most recent call last):
  File "/Users/bochkovoy/PycharmProjects/KiraProject/.venv/lib/python3.8/site-packages/django/utils/module_loading.py", line 30, in import_string
    return cached_import(module_path, class_name)
  File "/Users/bochkovoy/PycharmProjects/KiraProject/.venv/lib/python3.8/site-packages/django/utils/module_loading.py", line 16, in cached_import
    return getattr(module, class_name)
AttributeError: module 'main.context_processors' has no attribute 'contact_info'

The above exception was the direct cause of the following exception:

Traceback (most recent call last):
  File "/Users/bochkovoy/PycharmProjects/KiraProject/.venv/lib/python3.8/site-packages/django/core/handlers/exception.py", line 55, in inner
    response = get_response(request)
  File "/Users/bochkovoy/PycharmProjects/KiraProject/.venv/lib/python3.8/site-packages/django/core/handlers/base.py", line 197, in _get_response
    response = wrapped_callback(request, *callback_args, **callback_kwargs)
  File "/Users/bochkovoy/PycharmProjects/KiraProject/landscapedesign/main/views.py", line 24, in home
    return render(request, 'index.html', context)
  File "/Users/bochkovoy/PycharmProjects/KiraProject/.venv/lib/python3.8/site-packages/django/shortcuts.py", line 24, in render
    content = loader.render_to_string(template_name, context, request, using=using)
  File "/Users/bochkovoy/PycharmProjects/KiraProject/.venv/lib/python3.8/site-packages/django/template/loader.py", line 62, in render_to_string
    return template.render(context, request)
  File "/Users/bochkovoy/PycharmProjects/KiraProject/.venv/lib/python3.8/site-packages/django/template/backends/django.py", line 61, in render
    return self.template.render(context)
  File "/Users/bochkovoy/PycharmProjects/KiraProject/.venv/lib/python3.8/site-packages/django/template/base.py", line 173, in render
    with context.bind_template(self):
  File "/usr/local/opt/python@3.8/Frameworks/Python.framework/Versions/3.8/lib/python3.8/contextlib.py", line 113, in __enter__
    return next(self.gen)
  File "/Users/bochkovoy/PycharmProjects/KiraProject/.venv/lib/python3.8/site-packages/django/template/context.py", line 251, in bind_template
    processors = template.engine.template_context_processors + self._processors
  File "/Users/bochkovoy/PycharmProjects/KiraProject/.venv/lib/python3.8/site-packages/django/utils/functional.py", line 57, in __get__
    res = instance.__dict__[self.name] = self.func(instance)
  File "/Users/bochkovoy/PycharmProjects/KiraProject/.venv/lib/python3.8/site-packages/django/template/engine.py", line 116, in template_context_processors
    return tuple(import_string(path) for path in context_processors)
  File "/Users/bochkovoy/PycharmProjects/KiraProject/.venv/lib/python3.8/site-packages/django/template/engine.py", line 116, in <genexpr>
    return tuple(import_string(path) for path in context_processors)
  File "/Users/bochkovoy/PycharmProjects/KiraProject/.venv/lib/python3.8/site-packages/django/utils/module_loading.py", line 32, in import_string
    raise ImportError(
ImportError: Module "main.context_processors" does not define a "contact_info" attribute/class
"GET / HTTP/1.1" 500 115582
"GET / HTTP/1.1" 500 115582
Internal Server Error: /
Traceback (most recent call last):
  File "/Users/bochkovoy/PycharmProjects/KiraProject/.venv/lib/python3.8/site-packages/django/core/handlers/exception.py", line 55, in inner
    response = get_response(request)
  File "/Users/bochkovoy/PycharmProjects/KiraProject/.venv/lib/python3.8/site-packages/django/core/handlers/base.py", line 197, in _get_response
    response = wrapped_callback(request, *callback_args, **callback_kwargs)
  File "/Users/bochkovoy/PycharmProjects/KiraProject/landscapedesign/main/views.py", line 20, in home
    'middle_main_picture': middle_main_picture,
NameError: name 'middle_main_picture' is not defined
Internal Server Error: /
Traceback (most recent call last):
  File "/Users/bochkovoy/PycharmProjects/KiraProject/.venv/lib/python3.8/site-packages/django/core/handlers/exception.py", line 55, in inner
    response = get_response(request)
  File "/Users/bochkovoy/PycharmProjects/KiraProject/.venv/lib/python3.8/site-packages/django/core/handlers/base.py", line 197, in _get_response
    response = wrapped_callback(request, *callback_args, **callback_kwargs)
  File "/Users/bochkovoy/PycharmProjects/KiraProject/landscapedesign/main/views.py", line 20, in home
    'middle_main_picture': middle_main_picture,
NameError: name 'middle_main_picture' is not defined
"GET / HTTP/1.1" 500 63091
"GET / HTTP/1.1" 500 63091
Internal Server Error: /
Traceback (most recent call last):
  File "/Users/bochkovoy/PycharmProjects/KiraProject/.venv/lib/python3.8/site-packages/django/core/handlers/exception.py", line 55, in inner
    response = get_response(request)
  File "/Users/bochkovoy/PycharmProjects/KiraProject/.venv/lib/python3.8/site-packages/django/core/handlers/base.py", line 197, in _get_response
    response = wrapped_callback(request, *callback_args, **callback_kwargs)
  File "/Users/bochkovoy/PycharmProjects/KiraProject/landscapedesign/main/views.py", line 20, in home
    'middle_main_picture': middle_main_picture,
NameError: name 'middle_main_picture' is not defined
Internal Server Error: /
Traceback (most recent call last):
  File "/Users/bochkovoy/PycharmProjects/KiraProject/.venv/lib/python3.8/site-packages/django/core/handlers/exception.py", line 55, in inner
    response = get_response(request)
  File "/Users/bochkovoy/PycharmProjects/KiraProject/.venv/lib/python3.8/site-packages/django/core/handlers/base.py", line 197, in _get_response
    response = wrapped_callback(request, *callback_args, **callback_kwargs)
  File "/Users/bochkovoy/PycharmProjects/KiraProject/landscapedesign/main/views.py", line 20, in home
    'middle_main_picture': middle_main_picture,
NameError: name 'middle_main_picture' is not defined
"GET / HTTP/1.1" 500 63219
"GET / HTTP/1.1" 500 63219
Internal Server Error: /
Traceback (most recent call last):
  File "/Users/bochkovoy/PycharmProjects/KiraProject/.venv/lib/python3.8/site-packages/django/core/handlers/exception.py", line 55, in inner
    response = get_response(request)
  File "/Users/bochkovoy/PycharmProjects/KiraProject/.venv/lib/python3.8/site-packages/django/core/handlers/base.py", line 197, in _get_response
    response = wrapped_callback(request, *callback_args, **callback_kwargs)
  File "/Users/bochkovoy/PycharmProjects/KiraProject/landscapedesign/main/views.py", line 20, in home
    'middle_main_picture': middle_main_picture,
NameError: name 'middle_main_picture' is not defined
Internal Server Error: /
Traceback (most recent call last):
  File "/Users/bochkovoy/PycharmProjects/KiraProject/.venv/lib/python3.8/site-packages/django/core/handlers/exception.py", line 55, in inner
    response = get_response(request)
  File "/Users/bochkovoy/PycharmProjects/KiraProject/.venv/lib/python3.8/site-packages/django/core/handlers/base.py", line 197, in _get_response
    response = wrapped_callback(request, *callback_args, **callback_kwargs)
  File "/Users/bochkovoy/PycharmProjects/KiraProject/landscapedesign/main/views.py", line 20, in home
    'middle_main_picture': middle_main_picture,
NameError: name 'middle_main_picture' is not defined
"GET / HTTP/1.1" 500 62954
"GET / HTTP/1.1" 500 62954
